<?xml version="1.0"?>
<robot name="RhodentWheel" xmlns:xacro="http://www.ros.org/wiki/xacro">
    
    <xacro:include filename="$(find rhodent_description)/urdf/rhodent_properties.xacro" />
    
    <xacro:macro name="rhodent_wheel" params="name parent translation rotation color rotate">

        <link name="${name}">
            <inertial>
                <origin rpy="0 0 0" xyz="${WHEEL_COM}"/>
                <mass value="${WHEEL_M}" />
                <inertia ixx="${WHEEL_Ixx}" ixy="${WHEEL_Ixy}" ixz="${WHEEL_Ixz}" iyy="${WHEEL_Iyy}" iyz="${WHEEL_Iyz}" izz="${WHEEL_Izz}"/>
            </inertial>
            <visual>
                <origin rpy="${rotate} 0 0" xyz="0 0 0"/>
                <geometry>
                    <mesh filename="package://rhodent_description/meshes/wheel.STL" scale="1 1 1"/>
                </geometry>
                <material name="${color}"/>
            </visual>
            <collision name="collision">
                <origin rpy="0 0 0" xyz="0 0 0"/>
                <geometry>
                    <cylinder radius = "${WHEEL_RADIUS}" length = "0.0175"/>
                </geometry>
            </collision>
        </link>

        <joint name="${name}_joint" type="continuous">
            <origin xyz="${translation}" rpy="${rotation}"/>
            <parent link="${parent}" />
            <child link="${name}" />
            <axis xyz="0 0 1" />
            <limit effort="${U_MAX}" velocity="${V_MAX}" />
            <dynamics damping="${WHEEL_JOINT_DAMP}" />
        </joint>

        <gazebo reference="${name}">
            <mu1>0.7</mu1>
            <mu2>0.7</mu2>
            <slip1>0.2</slip1>
            <slip2>0.2</slip2>		
            <material>Gazebo/Grey</material>
        </gazebo>


        <transmission name="${name}_trans">
            <type>transmission_interface/SimpleTransmission</type>
            <joint name="${name}_joint">
                <hardwareInterface>hardware_interface/EffortJointInterface</hardwareInterface>
            </joint>
            <actuator name="${name}_motor">
                <hardwareInterface>hardware_interface/EffortJointInterface</hardwareInterface>
                <mechanicalReduction>1</mechanicalReduction>
            </actuator>
        </transmission>

    </xacro:macro>
</robot>